from dataclasses import dataclass, field
from logging import Logger
from typing import List, Optional

from discord import Message, AllowedMentions
from discord.interactions import Interaction
from discord.ext.commands import Context
from discord.ext.commands import errors as ce
from discord.app_commands import errors as ace

from commanderbot.core.commander_bot_base import (
    CommandErrorHandler,
    EventErrorHandler,
    AppCommandErrorHandler,
)
from commanderbot.lib import EventData, ResponsiveException
from commanderbot.lib.utils.interactions import send_or_followup, command_name


@dataclass
class ErrorHandling:
    log: Logger

    event_error_handlers: List[EventErrorHandler] = field(default_factory=list)
    command_error_handlers: List[CommandErrorHandler] = field(default_factory=list)
    app_command_error_handlers: List[AppCommandErrorHandler] = field(
        default_factory=list
    )

    def _get_root_error(self, error: Exception) -> Exception:
        if isinstance(error, (ce.CommandInvokeError, ace.CommandInvokeError)):
            return error.original
        else:
            return error

    def add_event_error_handler(self, handler: EventErrorHandler):
        self.event_error_handlers.append(handler)

    def add_command_error_handler(self, handler: CommandErrorHandler):
        self.command_error_handlers.append(handler)

    def add_app_command_error_handler(self, handler: AppCommandErrorHandler):
        self.app_command_error_handlers.append(handler)

    async def reply(
        self,
        ctx: Context,
        content: str,
        allowed_mentions: Optional[AllowedMentions] = None,
    ) -> Message:
        """Wraps `Context.reply()` with all mentions disabled by default."""
        return await ctx.message.reply(
            content,
            allowed_mentions=allowed_mentions or AllowedMentions.none(),
        )

    async def on_event_error(self, ex: Exception, event_data: EventData):
        # Extract the root error.
        error = self._get_root_error(ex)

        # Attempt to handle the error ourselves.
        handled = await self.try_handle_event_error(error, event_data)

        # Run the error through our registered event error handlers.
        for handler in self.event_error_handlers:
            try:
                if result := await handler(error, event_data, handled):
                    handled = result
            except:
                # If something went wrong here, print another exception to the console.
                self.log.exception("Handler for event errors caused another error:")

        # If it wasn't handled, re-raise so it can be printed to the console.
        if not handled:
            try:
                raise error
            except:
                self.log.exception(
                    f"Ignoring unhandled exception in event `{event_data.name}`"
                )

    async def try_handle_event_error(
        self, error: Exception, event_data: EventData
    ) -> bool:
        # TODO Can we handle certain types of event errors? #enhance
        return False

    async def on_command_error(self, ex: Exception, ctx: Context):
        # Extract the root error.
        error = self._get_root_error(ex)

        # Attempt to handle the error ourselves.
        handled = await self.try_handle_command_error(error, ctx)

        # Pipe the error through our registered command error handlers, regardless of
        # whether the error was handled. Handlers can decide on their own whether to do
        # anything with errors that have already been handled.
        for handler in self.command_error_handlers:
            try:
                if result := await handler(error, ctx, handled):
                    handled = result
            except:
                # If something went wrong here, print another exception to the console.
                self.log.exception("Handler for command errors caused another error:")

        # If it wasn't handled, re-raise so it can be printed to the console, and then
        # let the user know something went wrong.
        if not handled:
            try:
                raise error
            except:
                cog_name = ctx.cog.__cog_name__ if ctx.cog else None
                self.log.exception(
                    f"Ignoring unhandled exception in cog `{cog_name}` from command: `{ctx.command}`"
                )
            await self.reply(ctx, f"üî• Something went wrong trying to do that.")

    async def try_handle_command_error(self, error: Exception, ctx: Context) -> bool:
        match error:
            case ce.CommandNotFound():
                return True
            case ce.UserInputError():
                await self.reply(ctx, f"üò¨ Bad input: {error}")
                await ctx.send_help(ctx.command)
                return True
            case ce.MissingPermissions():
                await self.reply(ctx, f"üò† You don't have permission to do that.")
                return True
            case ce.BotMissingPermissions():
                await self.reply(ctx, f"üò≥ I don't have permission to do that.")
                return True
            case ce.NoPrivateMessage():
                await self.reply(ctx, f"ü§ê You can't do that in a private message.")
                return True
            case ce.CheckFailure():
                await self.reply(ctx, f"ü§î You can't do that.")
                return True
            case ResponsiveException():
                await error.respond(ctx)
                return True
            case _:
                return False

    async def on_app_command_error(self, ex: Exception, interaction: Interaction):
        # Extract the root error.
        error = self._get_root_error(ex)

        # Attempt to handle the error ourselves.
        handled = await self.try_handle_app_command_error(error, interaction)

        # Pipe the error through our registered app command error handlers, regardless of
        # whether the error was handled. Handlers can decide on their own whether to do
        # anything with errors that have already been handled.
        for handler in self.app_command_error_handlers:
            try:
                if result := await handler(error, interaction, handled):
                    handled = result
            except:
                # If something went wrong here, print another exception to the console.
                self.log.exception(
                    "Handler for app command errors caused another error:"
                )

        # If it wasn't handled, re-raise so it can be printed to the console, and then
        # let the user know something went wrong.
        if not handled:
            try:
                raise error
            except:
                self.log.exception(
                    f"Ignoring unhandled exception from command: `{command_name(interaction)}`"
                )

            await send_or_followup(
                interaction,
                f"üî• Something went wrong trying to do that.",
                ephemeral=True,
            )

    async def try_handle_app_command_error(
        self, error: Exception, interaction: Interaction
    ):
        match error:
            case ace.CommandNotFound():
                return True
            case ace.TransformerError():
                await send_or_followup(
                    interaction, f"üò¨ Bad input: {error.value}", ephemeral=True
                )
                return True
            case ace.MissingPermissions():
                await send_or_followup(
                    interaction,
                    f"üò† You don't have permission to do that.",
                    ephemeral=True,
                )
                return True
            case ace.BotMissingPermissions():
                await send_or_followup(
                    interaction,
                    f"üò≥ I don't have permission to do that.",
                    ephemeral=True,
                )
                return True
            case ace.NoPrivateMessage():
                await send_or_followup(
                    interaction,
                    f"ü§ê You can't do that in a private message.",
                    ephemeral=True,
                )
                return True
            case ace.CheckFailure():
                await send_or_followup(
                    interaction, f"ü§î You can't do that.", ephemeral=True
                )
                return True
            case ResponsiveException():
                await error.respond(interaction)
                return True
            case _:
                return False
